Workbook
Name _Hlk3285324: 補助事業計画書②!$A$26

Sheet 補助事業計画書②
A1: 【創業型】 | AJ1: （様式３）
AM2: ※補助上限額は、通常の場合は２００万円まで、
Q3: 補助事業計画書②【経費明細表・資金調達方法】 | AM3: インボイス特例希望の場合は２５０万円までを選択してください。
AO4: ←補助上限額を選択
S5: 名 称： | AO5: ←採択後の補助上限額を入力
AM6: 補助上限額 ⇒ | AO6: {=_xlfn.SWITCH(AN4,"ｲﾝﾎﾞｲｽ特例→２５０万",2500000,"通常→２００万円",2000000,"採択後金額入力",AN5,0)}
A7: Ⅱ．経費明細表【必須記入】
AJ8: （単位：円） | AM8: 判定 ⇒ | AN8: =ExpenseCategoryList!E41
A9: 経費区分 | G9: 内容・必要理由 | V9: 経費内訳 （単価×回数） | AE9: 補助対象経費 | AL9: 補助対象経費の「(税抜)／(税込)」選択欄は初期表示では空欄です。
AL10: ←プルダウンから「(税抜)／(税込)」のいずれかを選択ください
A11: ⑧委託・外注費 漫画制作費 【企画・シナリオ作成】 | G11: ターゲット分析、ストーリー構成、セリフ・コンテ作成。伴走支援「OToMo」のサービス価値を分かりやすく伝えるための漫画パンフレット企画。発注先:漫画広告制作専門業者 | V11: 80,000円×1式 | AE11: 80000 | AL11: (税込) | DD11: =IF($A11="",IF(OR($G11<>"",$V11<>"",$AE11>0),"×","〇"),"〇") | DE11: =IF($G11="",IF(OR($A11<>"",$V11<>"",$AE11>0),"×","〇"),"〇") | DF11: =IF($V11="",IF(OR($A11<>"",$G11<>"",$AE11>0),"×","〇"),"〇") | DG11: =IF($AE11<1,IF(OR($A11<>"",$G11<>"",$V11<>""),"×","〇"),"〇")
A12: ⑧委託・外注費 漫画制作費 【キャラクターデザイン】 | G12: 主要キャラクター3体(社長、従業員、デジ研スタッフ)のデザイン。表情差分・ポーズ差分制作、カラー設定。発注先:漫画広告制作専門業者 | V12: 200,000円×1式 | AE12: 200000 | AL12: (税込) | DD12: =IF($A12="",IF(OR($G12<>"",$V12<>"",$AE12>0),"×","〇"),"〇") | DE12: =IF($G12="",IF(OR($A12<>"",$V12<>"",$AE12>0),"×","〇"),"〇") | DF12: =IF($V12="",IF(OR($A12<>"",$G12<>"",$AE12>0),"×","〇"),"〇") | DG12: =IF($AE12<1,IF(OR($A12<>"",$G12<>"",$V12<>""),"×","〇"),"〇")
A13: ⑧委託・外注費 漫画制作費 【漫画作画（10ページ）】 | G13: ネーム作成・下書き・ペン入れ・トーン・仕上げ。ページ単価40,000円×10ページ。導入企業のストーリーを漫画化。発注先:漫画広告制作専門業者 | V13: 40,000円×10ページ | AE13: 400000 | AL13: (税込) | DD13: =IF($A13="",IF(OR($G13<>"",$V13<>"",$AE13>0),"×","〇"),"〇") | DE13: =IF($G13="",IF(OR($A13<>"",$V13<>"",$AE13>0),"×","〇"),"〇") | DF13: =IF($V13="",IF(OR($A13<>"",$G13<>"",$AE13>0),"×","〇"),"〇") | DG13: =IF($AE13<1,IF(OR($A13<>"",$G13<>"",$V13<>""),"×","〇"),"〇")
A14: ⑧委託・外注費 漫画制作費 【編集・DTP・デザイン】 | G14: ページレイアウト、文字入れ・効果処理、表紙デザイン、印刷用データ作成。発注先:漫画広告制作専門業者 | V14: 120,000円×1式 | AE14: 120000 | AL14: (税込) | DD14: =IF($A14="",IF(OR($G14<>"",$V14<>"",$AE14>0),"×","〇"),"〇") | DE14: =IF($G14="",IF(OR($A14<>"",$V14<>"",$AE14>0),"×","〇"),"〇") | DF14: =IF($V14="",IF(OR($A14<>"",$G14<>"",$AE14>0),"×","〇"),"〇") | DG14: =IF($AE14<1,IF(OR($A14<>"",$G14<>"",$V14<>""),"×","〇"),"〇")
A15: ②広報費 ノベルティ制作費 | G15: パンフレット配布時の同封用ノベルティ。約9,000個制作。手に取りやすくし、記憶に残りやすくするため。デザインはキャラクターを活用しブランド統一。優先地域(行田市、さいたま市、台東区等)への配布に使用。発注先:ノベルティ製造業者 | V15: 700,000円×1式（約9,000個） | AE15: 700000 | AL15: (税込) | DD15: =IF($A15="",IF(OR($G15<>"",$V15<>"",$AE15>0),"×","〇"),"〇") | DE15: =IF($G15="",IF(OR($A15<>"",$V15<>"",$AE15>0),"×","〇"),"〇") | DF15: =IF($V15="",IF(OR($A15<>"",$G15<>"",$AE15>0),"×","〇"),"〇") | DG15: =IF($AE15<1,IF(OR($A15<>"",$G15<>"",$V15<>""),"×","〇"),"〇")
A16: ②広報費 立て看板購入費 | G16: 営業所前(行田市、さいたま市)に設置する立て看板2基。「デジタル化のお悩み相談」等を訴求し、地域での認知度向上を図る。行田・さいたま営業所前に常設。 | V16: 4,989円×2基 | AE16: 9978 | AL16: (税込)
A17: ②広報費 チラシ印刷費 | G17: 漫画パンフレット10万部の印刷。A4サイズ・10ページ冊子。埼玉県・北関東・東京都台東区の中小企業へ配布用。印刷完了後の写真を証拠として提出予定。発注先:印刷業者（相見積もり取得予定） | V17: 178,650円×1式（10万部） | AE17: 178650 | AL17: (税込)
A18: ⑧委託・外注費 ポスティング委託費 | G18: 10万部のパンフレット配布業務。配布先:埼玉県5万部、北関東(群馬・栃木)3.5万部、東京都台東区1.5万部。従業員50名以下の事業所を中心にリスト化。配布完了報告書、配布先リスト、実施写真を提出予定。補助事業期間内に全10万部の配布完了。発注先:ポスティング業者 | V18: 950,000円×1式（10万部配布） | AE18: 950000 | AL18: (税込)
A19: ③ウェブサイト関連費 LP(ランディングページ)作成費 【ワイヤーフレーム設計】 | G19: サイト構成・レイアウト設計。OToMoサービス詳細説明、導入事例・お客様の声、料金プラン、無料相談申し込みフォームの設計。発注先:WEB制作会社（外部エンジニア） | V19: 50,000円×1式 | AE19: 50000 | AL19: (税込)
A20: ③ウェブサイト関連費 LP(ランディングページ)作成費 【デザイン制作】 | G20: ビジュアルデザイン、画像作成・編集。漫画キャラクターを活用したブランド統一デザイン。漫画パンフレットからの問い合わせ受け皿。発注先:WEB制作会社（外部エンジニア） | V20: 60,000円×1式 | AE20: 60000 | AL20: (税込)
A21: ③ウェブサイト関連費 LP(ランディングページ)作成費 【コーディング】 | G21: HTML/CSS/JavaScriptコーディング、レスポンシブ対応。スマートフォン・タブレット対応。発注先:WEB制作会社（外部エンジニア） | V21: 60,000円×1式 | AE21: 60000 | AL21: (税込)
A22: ③ウェブサイト関連費 LP(ランディングページ)作成費 【問い合わせフォーム連携】 | G22: フォーム機能実装、自動返信メール設定、管理画面設定。漫画パンフレットからの問い合わせ受け皿として機能。発注先:WEB制作会社（外部エンジニア） | V22: 30,000円×1式 | AE22: 30000 | AL22: (税込)
A23: ③ウェブサイト関連費 LINE公式アカウント構築費 【アカウント開設・基本設定】 | G23: LINE公式アカウント開設、プロフィール設定、基本機能設定。気軽に問い合わせできる窓口として構築。発注先:LINE構築専門業者（外部エンジニア） | V23: 30,000円×1式 | AE23: 30000 | AL23: (税込)
A24: ③ウェブサイト関連費 LINE公式アカウント構築費 【自動応答メッセージ設定】 | G24: 自動応答シナリオ作成、キーワード応答設定、応答メッセージ作成。電話やメールよりも気軽に問い合わせできる窓口。発注先:LINE構築専門業者（外部エンジニア） | V24: 40,000円×1式 | AE24: 40000 | AL24: (税込)
A25: ③ウェブサイト関連費 LINE公式アカウント構築費 【リッチメニュー作成】 | G25: リッチメニューデザイン・設定、導線設計、リンク設定。サービス案内、問い合わせ、事例紹介等のメニュー構築。発注先:LINE構築専門業者（外部エンジニア） | V25: 30,000円×1式 | AE25: 30000 | AL25: (税込)
A26: ③ウェブサイト関連費 LINE公式アカウント構築費 【配信設定・タグ管理】 | G26: セグメント配信設定、タグ管理システム構築、配信スケジュール設定。問い合わせ属性に応じた適切な情報配信。発注先:LINE構築専門業者（外部エンジニア） | V26: 30,000円×1式 | AE26: 30000 | AL26: (税込)
A27: ③ウェブサイト関連費 LINE公式アカウント構築費 【問い合わせ対応フロー構築】 | G27: 問い合わせ受付フロー設計、対応マニュアル作成、管理画面設定。効率的な問い合わせ対応体制の構築。発注先:LINE構築専門業者（外部エンジニア） | V27: 20,000円×1式 | AE27: 20000 | AL27: (税込)
A28: （1）補助対象経費小計（ウェブサイト関連費を除く） | AE28: =ExpenseCategoryList!K$2 | AM28: ▼判定式 | AN28: 端数 | AO28: 経費内比率 | AP28: ウェブサイト関連費以外の申請補助額
A29: （2）補助金交付申請額（ウェブサイト関連費を除く） | AM29: =ExpenseCategoryList!E29 | AN29: =IF(AP17=AR17,ExpenseCategoryList!I14,"") | AO29: =ExpenseCategoryList!J38 | AP29: =ExpenseCategoryList!I29 | AQ29: ～ | AR29: =ExpenseCategoryList!G29
A30: （3）ウェブサイト関連費に係る補助対象経費小計 | AE30: =ExpenseCategoryList!$Q$2
A31: （4）ウェブサイト関連費に係る交付申請額 | AE31: =ExpenseCategoryList!H40 | AM31: =ExpenseCategoryList!E31 | AN31: =IF(AP17=AR17,ExpenseCategoryList!I18,"") | AO31: =ExpenseCategoryList!J40
A32: （5）補助対象経費合計 （a）＋（c） | AE32: =ExpenseCategoryList!$D$2
A33: （6）補助金交付申請額合計 （b）＋（d） | AE33: =ExpenseCategoryList!J20 | AK33: =ExpenseCategoryList!E46 | AM33: =ExpenseCategoryList!E33 | AN33: =IF(AP17=AR17,ExpenseCategoryList!I22,"") | AO33: 申請額内比率
A34: （d）が（f）の1/4以内であるか（「いいえ」の場合は申請できません） | AE34: =ExpenseCategoryList!$R$2 | AM34: =ExpenseCategoryList!E34 | AO34: =ExpenseCategoryList!J42
A35: ※経費区分には、「①機械装置等費」から「⑧委託・外注費」までの各費目を記入してください。
A36: ※経費の内訳に関しては、内容がわかるように記載してください。 | AM36: 上限補助額： | AN36: =ExpenseCategoryList!E38
A37: ※補助対象経費の消費税（税抜・税込）区分については、別紙「参考資料」の「１２．消費税等仕入控除税額」を参照のこと。 | AM37: 補助率 ： | AN37: =ExpenseCategoryList!E40
A38: ※「（4）ウェブサイト関連費に係る交付申請額」については、「（6）補助金交付申請額合計」の1/4以内となるように記入してください。 | AM38: =ExpenseCategoryList!E48 & ExpenseCategoryList!E49
A39: 記載にあたっては、「様式3_経費明細表(Excel)」をご使用ください。
A40: ※補助事業の実績によりウェブサイト関連費における補助金額が減額となる場合があります。
...

Sheet ExpenseCategoryList
A1: No | B1: 区分名称 | C1: 処理フラグ(1:通常、2:設備処分費) | D1: ⑤対象経費合計 | E1: 最高金額 | F1: ⑤対象経費合計*2/3 | G1: ⑥交付申請額合計 上限チェック後 | H1: ②交付申請額合計 | I1: ②ｳｪﾌﾞｻｲﾄ関連費除 交付申請額*2/3 | J1: ②ｳｪﾌﾞｻｲﾄ関連費除 交付申請額上限 | K1: ①ｳｪﾌﾞｻｲﾄ関連費除 対象経費小計 | L1: ④条件２ 対象経費小計*2/3 | M1: ④条件１－１ 補助対象経費合計/4 | N1: ④条件１－２ 経費小計上限チェック | O1: ④ｳｪﾌﾞｻｲﾄ関連費 交付申請額 | P1: ④ｳｪﾌﾞｻｲﾄ関連費の判定 | Q1: ③ｳｪﾌﾞｻｲﾄ関連費 合計 | R1: （d）が（f）の1/4以内であるか | S1: 補助対象経費合計/2 | T1: ⑨設備処分費 合計 | U1: ⑨設備処分費の判定 | V1: チェックボックスの条件（未チェック） | W1: チェックボックスの条件（複数チェック） | X1: チェックボックスの条件（赤字事業者チェック） | Y1: チェックボックスの条件（総合判定）
A2: 1 | B2: ①機械装置等費 | C2: 1 | D2: =SUM(補助事業計画書②!AE16+補助事業計画書②!AE18) | E2: =補助事業計画書②!AO6 | F2: =ROUNDDOWN(補助事業計画書②!AE20*2/3,0) | G2: =IF(F2>E2,E2,F2) | H2: =G33 | I2: =ROUNDDOWN(補助事業計画書②!AE16*2/3,0) | J2: =H2-O2 | K2: =SUMIF(補助事業計画書②!A11:A15,"<>③ウェブサイト関連費",補助事業計画書②!AE11:AE15) | L2: =ROUNDDOWN(補助事業計画書②!AE18*2/3,0) | M2: =ROUNDDOWN(H2/4,0) | N2: =IF(M2>500000,500000,M2) | O2: =IF(N2>L2,L2,N2) | P2: =IF(L2<=N2,"○","×") | Q2: =SUMIF(補助事業計画書②!A11:A15,"③ウェブサイト関連費",補助事業計画書②!AE11:AE15) | R2: =IF(補助事業計画書②!AE17="","いいえ",IF(補助事業計画書②!AE17=0,"いいえ",IF(補助事業計画書②!AE21<補助事業計画書②!AE19*4,"いいえ","はい"))) | S2: =ROUNDDOWN(補助事業計画書②!AE20/2,0) | T2: =SUMIF(補助事業計画書②!A:A,"⑨設備処分費",補助事業計画書②!AE:AE) | U2: =IF(T2<=S2,"○","×") | V2: ="○" | W2: ="○" | X2: ="○" | Y2: =IF(AND(V2="○",W2="○",X2="○"),"○","×")
A3: 2 | B3: ②広報費 | C3: 1 | G3: EとFの小さいほう | I3: 以外の2/3 | J3: H-I | K3: 以外の合計 | L3: 関連費*2/3 | M3: Hの1/4
A4: 3 | B4: ③ウェブサイト関連費 | C4: 1
A5: 4 | B5: ④展示会等出展費 | C5: 1
A6: 5 | B6: ⑤旅費 | C6: 1 | D6: 計算
A7: 6 | B7: ⑥新商品開発費 | C7: 1 | L7: 計算方法シートの | N7: 計算方法シートの
A8: 7 | B8: ⑦借料 | C8: 1 | E8: 可変 | G8: 補助率 | H8: ="2/3" | L8: 申請額が一意になる場合 | N8: 申請額に範囲がある場合
A9: 8 | B9: ⑧委託・外注費 | C9: 1 | G9: 補助率文言 | H9: ="(1)×補助率 " & H8 &"(※)以内(円未満切捨て)"
G10: 補助率文言 | H10: ="((6)の1/4を上限(最大50万円))、(c)×補助率 " & H8 & " (※)以内(円未満切捨て)" | N10: Web以外の申請額が最大 | P10: Webの申請額が最大
E11: Web以外 (下段端数) | F11: a経費(=K2) | G11: ="a*2/3" | H11: ="(" & "a*2/3" & ") /3" | I11: b.補助額の最大値 | L11: b.Web以外の申請額 | N11: b.Web以外の申請額 | O11: ～ | P11: b.Web以外の申請額
D12: 12 | F12: =K2 | G12: =ROUNDDOWN(F12*2/3,0) | H12: =ROUNDDOWN(G12/3,0) | I12: =G12 | L12: =IF(I20<=G20,I12,"") | N12: =IF(I20<=G20,"",IF(I12>G20,G20,I12)) | P12: =IF(I20<=G20,"",G20-P16)
D13: 13 | H13: =ROUNDDOWN(G12/3,3)
D14: 14 | G14: =ROUNDDOWN(F12*2/3,3) - G12 | H14: =ROUNDDOWN(G12/3,3) - H12 | I14: =G14
D15: 15 | E15: Web (下段端数) | F15: c経費(=Q2) | G15: ="c*2/3" | H15: ="a*2/9" | I15: d.補助額の最大値 と50万の小さい方 | J15: d.補助額の最大値 | L15: d.Webの申請額 | N15: d.Webの申請額 | P15: d.Webの申請額
D16: 16 | F16: =Q2 | G16: =ROUNDDOWN(F16*2/3,0) | H16: =ROUNDDOWN(F12*2/9,0) | I16: =IF(J16<500000,J16,500000) | J16: =IF(IF(G16>H12,H12,G16)>H20,H20,IF(G16>H12,H12,G16)) | L16: =IF(I20<=G20,I16,"") | M16: =IF(L16="","",IF(L16*4>L20,"×","〇")) | N16: =IF(I20<=G20,"",G20-N12) | P16: =IF(I20<=G20,"",IF(ROUNDDOWN(G20/4,0)>I16,I16,ROUNDDOWN(G20/4,0)))
D17: 17 | G17: =ROUNDDOWN(F16*2/3,3) | H17: =ROUNDDOWN(F12*2/9,3) | I17: =IF(J16<500000,J17,500000) | J17: =IF(IF(G17>H13,H13,G17)>H21,H21,IF(G17>H13,H13,G17))
D18: 18 | G18: =ROUNDDOWN(F16*2/3,3)-G16 | H18: =ROUNDDOWN(F12*2/9,3) - H16 | I18: =IF(J16<500000,J18,0) | J18: =IF(IF(G17>H13,H13,G17)>H21,H22,IF(G17>H13,H14,G18))
D19: 19 | G19: 最大補助額(=E2) | H19: f/4 | I19: b+dの単純合計 | J19: f.最終補助額 | L19: f.最終補助額 | N19: f.最終補助額 | P19: f.最終補助額
D20: 20 | G20: =E2 | H20: =ROUNDDOWN(G20/4,0) | I20: =I12+I16 | J20: =IF(G20>I20+J22,I20+J22,G20) | L20: =IF(I20<=G20,I20,"") | N20: =IF(I20<=G20,"",N12+N16) | P20: =IF(I20<=G20,"",P12+P16)
D21: 21 | H21: =ROUNDDOWN(G20/4,3)
D22: 22 | H22: =ROUNDDOWN(G20/4,3) - H20 | I22: =I14+I18 | J22: =IF(I20<G20,IF(I22>=1,1,0),0) | K22: ←端数から算出した加算値
D23: 23
D25: 計算結果(表示用)
E27: ▼判定式 | G27: Web以外の申請額が最大 | I27: Webの申請額が最大
E28: b.Web以外の申請額 | G28: b.Web以外の申請額 | H28: ～ | I28: b.Web以外の申請額
D29: 29 | E29: =IF(補助事業計画書②!AE17=0,"×",IF(補助事業計画書②!AE17<I29,"×",IF(補助事業計画書②!AE17>G29,"×","〇"))) | F29: 29 | G29: =IF(I20<=G20,I12,IF(I12>G20,G20,I12)) | I29: =IF(I20<=G20,I12,G20-P16)
E30: d.Webの申請額 | G30: d.Webの申請額 | I30: d.Webの申請額
D31: 30 | E31: =IF(補助事業計画書②!AE19>I31,"×",IF(補助事業計画書②!AE19<G31,"×","〇")) | F31: 30 | G31: =IF(I20<=G20,I16,G20-N12) | I31: =IF(I20<=G20,I16,IF(ROUNDDOWN(G20/4,0)>I16,I16,ROUNDDOWN(G20/4,0)))
E32: f.最終補助額 | G32: f.最終補助額 | I32: f.最終補助額
D33: 33 | E33: 〇 | F33: 33 | G33: =IF(I20<=G20,I20,N12+N16) | I33: =IF(I20<=G20,I20,I29+I31)
D34: （d）が（f）の1/4以内であるか | E34: =IF(補助事業計画書②!AE17="","×",IF(補助事業計画書②!AE17=0,"×",IF(補助事業計画書②!AE21<補助事業計画書②!AE19*4,"×","〇")))
G36: 入力値 | I36: 経費内比率
D37: 上限補助額 | E37: =E2 | F37: F37 | G37: (a)以外経費 | H37: =K2 | I37: 以外補助額/以外経費
D38: 編集 | E38: =IF(V2="×","",DBCS(FIXED(E37,0)) & "円") | F38: F38 | G38: (b)以外補助額 | H38: =補助事業計画書②!$AE$17 | I38: =IF(AND(H37=0,H38=0),0,IF(OR(H37=0,H37=""),"",ROUNDDOWN(H38*100/H37,2))) | J38: =IF(補助事業計画書②!AE17="","",IF(I38="","",TEXT(I38,"##0.00")&"%"))
D39: 補助率 | E39: =H8 | F39: F39 | G39: (c)Web経費 | H39: =Q2 | I39: Web補助額/Web経費
D40: 編集 | E40: =IF(V2="×","",DBCS(E39) ) | F40: F40 | G40: (d)Web補助額 | H40: =H42-H38 | I40: =IF(H41=0,"",IF(AND(H39=0,H40=0),0,IF(OR(H39=0,H39=""),"",ROUNDDOWN(H40*100/H39,2)))) | J40: =IF(補助事業計画書②!AE17="","",IF(I40="","",TEXT(I40,"##0.00")&"%"))
D41: 補助上限額チェック | E41: =IF(AND(補助事業計画書②!AO6>=1,補助事業計画書②!AO6<=2500000),"○","×(補助上限額（通常は200万円・ｲﾝﾎﾞｲｽ特例は250万円まで）を入力してください。)") | F41: F41 | G41: (e)経費合計 | H41: =D2 | I41: Web補助額/補助額計
F42: F42 | G42: (f)補助額合計 | H42: =H2 | I42: =IF(H41=0,"",IF(H40=0,0,IF(OR(H42=0,H42="",H39=0,H39=""),"",ROUNDDOWN(H40*100/H42,2)))) | J42: =IF(補助事業計画書②!AE17="","",IF(I42="","",TEXT(I42,"##0.00") & "%"))
D45: コメント(表示用)
...
